### 错误处理
##### try

```
try:
    print('try...')
    r = 10 / 0
    print('result:', r)
except ZeroDivisionError as e:
    print('except:', e)
finally:
    print('finally...')
print('END')
```

###### 当我们认为某些代码可能会出错时，就可以用try来运行这段代码，如果执行出错，则后续代码不会继续执行，而是直接跳转至错误处理代码，即except语句块，执行完except后，如果有finally语句块，则执行finally语句块，至此，执行完毕。

###### 上面的代码在计算10 / 0时会产生一个除法运算错误：


```
try...
except: division by zero
finally...
END
```
###### 从输出可以看到，当错误发生时，后续语句print('result:', r)不会被执行，except由于捕获到ZeroDivisionError，因此被执行。最后，finally语句被执行。然后，程序继续按照流程往下走。

###### 如果把除数0改成2，则执行结果如下：


```
try...
result: 5
finally...
END
```

###### 由于没有错误发生，所以except语句块不会被执行，但是finally如果有，则一定会被执行（可以没有finally语句）。
###### 你还可以猜测，错误应该有很多种类，如果发生了不同类型的错误，应该由不同的except语句块处理。没错，可以有多个except来捕获不同类型的错误：


```
try:
    print('try...')
    r = 10 / int('a')
    print('result:', r)
except ValueError as e:
    print('ValueError:', e)
except ZeroDivisionError as e:
    print('ZeroDivisionError:', e)
finally:
    print('finally...')
print('END')
```
###### Python的错误其实也是class，所有的错误类型都继承自BaseException，所以在使用except时需要注意的是，它不但捕获该类型的错误，还把其子类也“一网打尽”。比如：


```
try:
    foo()
except ValueError as e:
    print('ValueError')
except UnicodeError as e:
    print('UnicodeError')
```

###### 第二个except永远也捕获不到UnicodeError，因为UnicodeError是ValueError的子类，如果有，也被第一个except给捕获了。
#####  调用栈

```
def foo(s):
    return 10 / int(s)

def bar(s):
    return foo(s) * 2

def main():
    bar('0')

main()
```

###### 执行，结果如下：


```
$ python3 err.py
Traceback (most recent call last):
  File "err.py", line 11, in <module>
    main()
  File "err.py", line 9, in main
    bar('0')
  File "err.py", line 6, in bar
    return foo(s) * 2
  File "err.py", line 3, in foo
    return 10 / int(s)
ZeroDivisionError: division by zero
```
###### 错误信息第1行：

###### Traceback (most recent call last):
###### 告诉我们这是错误的跟踪信息。

###### 第2~3行：


```
File "err.py", line 11, in <module>
    main()
```

###### 调用main()出错了，在代码文件err.py的第11行代码，但原因是第9行：


```
File "err.py", line 9, in main
    bar('0')
```

###### 调用bar('0')出错了，在代码文件err.py的第9行代码，但原因是第6行：


```
File "err.py", line 6, in bar
    return foo(s) * 2
```

###### 原因是return foo(s) * 2这个语句出错了，但这还不是最终原因，继续往下看：


```
File "err.py", line 3, in foo
    return 10 / int(s)
```

###### 原因是return 10 / int(s)这个语句出错了，这是错误产生的源头，因为下面打印了：


```
ZeroDivisionError: integer division or modulo by zero
```

###### 根据错误类型ZeroDivisionError，我们判断，int(s)本身并没有出错，但是int(s)返回0，在计算10 / 0时出错，至此，找到错误源头
##### 记录错误
###### Python内置的logging模块可以非常容易地记录错误信息：


```
import logging

def foo(s):
    return 10 / int(s)

def bar(s):
    return foo(s) * 2

def main():
    try:
        bar('0')
    except Exception as e:
        logging.exception(e)

main()
print('END')
```
###### 同样是出错，但程序打印完错误信息后会继续执行，并正常退出：


```
$ python3 err_logging.py
ERROR:root:division by zero
Traceback (most recent call last):
  File "err_logging.py", line 13, in main
    bar('0')
  File "err_logging.py", line 9, in bar
    return foo(s) * 2
  File "err_logging.py", line 6, in foo
    return 10 / int(s)
ZeroDivisionError: division by zero
END
```

###### 通过配置，logging还可以把错误记录到日志文件里，方便事后排查。
##### 抛出错误
###### 抛出异常了 过后当前函数后面就不继续参与运行了(避免程序运行的错误)
###### 抛出异常了后捕获异常的语句就不会报错了因为↑


###### 我们自己编写的函数也可以抛出错误。

```
class FooError(ValueError):
    pass

def foo(s):
    n = int(s)
    if n==0:
        raise FooError('invalid value: %s' % s)
    return 10 / n

foo('0')
```
###### 执行，可以最后跟踪到我们自己定义的错误：


```
$ python3 err_raise.py 
Traceback (most recent call last):
  File "err_throw.py", line 11, in <module>
    foo('0')
  File "err_throw.py", line 8, in foo
    raise FooError('invalid value: %s' % s)
__main__.FooError: invalid value: 0
```
###### 最后，我们来看另一种错误处理的方式：



```
def foo(s):
    n = int(s)
    if n==0:
        raise ValueError('invalid value: %s' % s)
    return 10 / n

def bar():
    try:
        foo('0')
    except ValueError as e:
        print('ValueError!')
        raise

bar()
```

###### 在bar()函数中，我们明明已经捕获了错误，但是，打印一个ValueError!后，又把错误通过raise语句抛出去了，这不有病么？

###### 其实这种错误处理方式不但没病，而且相当常见。捕获错误目的只是记录一下，便于后续追踪。但是，由于当前函数不知道应该怎么处理该错误，所以，最恰当的方式是继续往上抛，让顶层调用者去处理。好比一个员工处理不了一个问题时，就把问题抛给他的老板，如果他的老板也处理不了，就一直往上抛，最终会抛给CEO去处理。